Workbook

Sheet Notas_CPerez
A1: Autor: | B1: Camilo Pérez Núñez
A2: Última
A3: Modificación: | B3: 41396
A5: La base de datos principal es la que se encuentra en la hoja "DatosVinculos", la cual contiene series construidas desde 1986q1 hasta 2012q4.
A6: En su mayoría corresponden a datos efectivos, de lo contrario se destaca el contenido de la celda con letra roja, la explicación de los datos construidos se encuentra en las Notas.
A7: La hoja "DatosSinVinculos", corresponde a la base consolidada sin vinculos, el resto de las hojas donde se realizan la mayoria de los empalmes estan ocultas.
A9: Notas:
A10: 1) Gran parte de los datos fueron extraidos de la Web (bcentral.cl) y son de carácter público
A11: 2) Las series del PIB y derivados, y los componentes del gasto, son datos efectivos con al metodología de encadenamiento a partir de 1996q1 en adelante. Hacia atras se empalman en variación anual hasta 1986q1 con las series construidas con metodología a base fijo.
A12: 3) Para construir el Pib Nominal entre 1986q1 y 1989q4 se aplica a los datos anuales de CCNN método de desagregación temporal Chow-Lin utilizando como control el PIB Real.
A13: 4) La Balanza Comercial Nominal, se construye en base a datos publicos a partir de 1996q1 hasta 2012q4, hacia atrás se empalma con una serie construida por desagregación temporal con el método Chow-Lin utilizando de input los datos anuales oficiales de balanza comercial y como variable de control la diferencia entre (X-M).
A14: 5) De la Serie Cuenta Corriente hay datos trimestrales desde 1996q1 hasta 2012q4, hacia atrás se empalma con una serie construida por desagregación temporal con el método Chow-Lin utilizando de input los datos anuales oficiales de cuenta corriente y como variable de control la diferencia entre (X-M).
A15: 6) La serie Meta de IPC es de uso interno, no es pública. La serie IPC Meta 2, corresponde a datos efectivos desde 1991q1 en adelante. Para completar la serie hasta 1986q1 se empalma con filtro hp 1600 a var. a/a del ipc.
A16: 7) Tanto las Series IPE como PIB externo (socios comerciales), por construccción estan desestacionalizadas.
A17: 8) Para las series IPCSAE, IPCSAE Bienes e IPCSAE Servicios hay datos desde 1989q2. Para completar datos hacia atrás se utiliza empalme según variación anual del IPC.
... A26: 17) La serie EMBI Chile 2 se construye con datos efectivos a partir de 1999q2, hacia atrás se utiliza empalme con distintas medidas de spread hasta 1991q1.

Sheet Empleo
A1: VALORES ESTIMADOS
A2: Año | B2: Mes | C2: Fecha | D2: Empleo Total Resto | E2: Empleo Total Resto SA | F2: Horas Resto | G2: Horas Resto SA | H2: Empleo Resto con agro y sin pesca | I2: Empleo Resto con agro y sin pesca SA | J2: Horas Resto con agro | K2: Horas Resto con agro SA | N2: Empleo Total Resto | O2: Empleo Total Resto SA | P2: Horas Resto | Q2: Horas Resto SA
A3: =YEAR(C3) -> 1986 | B3: =MONTH(C3) -> 3 | C3: 31472 | D3: 3034530.7 | E3: 3063628.3 | F3: 44.692947 | G3: 45.124091 | H3: 3729821.9 | I3: 3730405.3 | J3: 45.412215 | K3: 45.437662 | L3: 1 | M3: 1986T1 | N3: 3034530.7 | O3: 3063628.3 | P3: 44.692947 | Q3: 45.124091
A4: =YEAR(C4) -> 1986 | B4: =MONTH(C4) -> 4 | C4: 31503 | D4: 3054712.9 | E4: 3072306.3 | F4: 45.50087 | G4: 45.364405 | H4: 3754231.2 | I4: 3757664.6 | J4: 45.947561 | K4: 45.477736 | L4: 2 | M4: 1986T2 | N4: 3114314.7 | O4: 3090735.2 | P4: 46.034659 | Q4: 45.631548
A5: =YEAR(C5) -> 1986 | B5: =MONTH(C5) -> 5 | C5: 31533 | D5: 3075603.1 | E5: 3069906.8 | F5: 46.095575 | G5: 45.427785 | H5: 3763679.5 | I5: 3765039.9 | J5: 46.051659 | K5: 45.480781 | L5: 3 | M5: 1986T3 | N5: 3161638.8 | O5: 3139220.4 | P5: 44.461316 | Q5: 44.887846
A6: =YEAR(C6) -> 1986 | B6: =MONTH(C6) -> 6 | C6: 31564 | D6: 3114314.7 | E6: 3090735.2 | F6: 46.034659 | G6: 45.631548 | H6: 3783099.6 | I6: 3788164.9 | J6: 45.615946 | K6: 45.359474 | L6: 4 | M6: 1986T4 | N6: 3137479.1 | O6: 3157510.1 | P6: 46.166941 | Q6: 46.003329
A7: =YEAR(C7) -> 1986 | B7: =MONTH(C7) -> 7 | C7: 31594 | D7: 3140530.1 | E7: 3108184.2 | F7: 45.841103 | G7: 45.628952 | H7: 3804019.3 | I7: 3808485.1 | J7: 45.386586 | K7: 45.599525 | L7: 5 | M7: 1987T1 | N7: 3147932.4 | O7: 3178129.6 | P7: 45.003883 | Q7: 45.404197
A8: =YEAR(C8) -> 1986 | B8: =MONTH(C8) -> 8 | C8: 31625 | D8: 3159258.2 | E8: 3129778.8 | F8: 45.573923 | G8: 45.499859 | H8: 3828764.3 | I8: 3833530.9 | J8: 45.303009 | K8: 45.650512 | L8: 6 | M8: 1987T2 | N8: 3220168.6 | O8: 3196015.6 | P8: 45.003129 | Q8: 44.665485
A9: =YEAR(C9) -> 1986 | B9: =MONTH(C9) -> 9 | C9: 31656 | D9: 3161638.8 | E9: 3139220.4 | F9: 44.461316 | G9: 44.887846 | H9: 3843614.3 | I9: 3844816.3 | J9: 44.492809 | K9: 45.291854 | L9: 7 | M9: 1987T3 | N9: 3216438 | O9: 3192960.9 | P9: 44.747245 | Q9: 45.072519
A10: =YEAR(C10) -> 1986 | B10: =MONTH(C10) -> 10 | C10: 31686 | D10: 3160968.6 | E10: 3147900.4 | F10: 44.593515 | G10: 44.950591 | H10: 3857882.5 | I10: 3855261.8 | J10: 44.725339 | K10: 45.110844 | L10: 8 | M10: 1987T4 | N10: 3233010.3 | O10: 3253686.8 | P10: 45.617001 | Q10: 45.395379
A11: =YEAR(C11) -> 1986 | B11: =MONTH(C11) -> 11 | C11: 31717 | D11: 3144117.4 | E11: 3143791.7 | F11: 44.945038 | G11: 44.949466 | H11: 3853486.1 | I11: 3845753.7 | J11: 45.107255 | K11: 45.227414 | L11: 9 | M11: 1988T1 | N11: 3258670 | O11: 3290151.3 | P11: 44.782103 | Q11: 45.187321
A12: =YEAR(C12) -> 1986 | B12: =MONTH(C12) -> 12 | C12: 31747 | D12: 3137479.1 | E12: 3157510.1 | F12: 46.166941 | G12: 46.003329 | H12: 3866772.9 | I12: 3862557.1 | J12: 46.319481 | K12: 45.961702 | L12: 10 | M12: 1988T2 | N12: 3384826.7 | O12: 3360078.5 | P12: 46.200887 | Q12: 45.883847
A13: =YEAR(C13) -> 1987 | B13: =MONTH(C13) -> 1 | C13: 31778 | D13: 3134626.1 | E13: 3161788.7 | F13: 45.452396 | G13: 45.460614 | H13: 3876857.3 | I13: 3872513.6 | J13: 45.856614 | K13: 45.560787 | L13: 11 | M13: 1988T3 | N13: 3459808 | O13: 3433244.9 | P13: 45.789391 | Q13: 46.151104
A14: =YEAR(C14) -> 1987 | B14: =MONTH(C14) -> 2 | C14: 31809 | D14: 3135036.4 | E14: 3167876.5 | F14: 44.700104 | G14: 45.183147 | H14: 3883208.2 | I14: 3881108.1 | J14: 45.408583 | K14: 45.466508 | L14: 12 | M14: 1988T4 | N14: 3465894.4 | O14: 3488547.1 | P14: 46.008931 | Q14: 45.764282
... A110: =YEAR(C110) -> 1995 | B110: =MONTH(C110) -> 2 | C110: 34731 | D110: 4331269.1 | E110: 4369669.4 | F110: 45.415756 | G110: 46.275924 | H110: 5126473.7 | I110: 5126492.6 | J110: 45.613579 | K110: 46.155228 | L110: 108 | M110: 2012T4 | N110: 6582462.5 | O110: 6591955.4 | P110: 39.691614 | Q110: 39.235313
A111: =YEAR(C111) -> 1995 | B111: =MONTH(C111) -> 3 | C111: 34759 | D111: 4325876.3 | E111: 4361411.6 | F111: 45.57587 | G111: 46.004248 | H111: 5116256.6 | I111: 5113559 | J111: 45.824876 | K111: 45.883763 | L111: 109
A112: =YEAR(C112) -> 1995 | B112: =MONTH(C112) -> 4 | C112: 34790 | D112: 4329645.3 | E112: 4356226.3 | F112: 46.1336 | G112: 45.923003 | H112: 5117640.7 | I112: 5119977.8 | J112: 46.129329 | K112: 45.835408 | L112: 110
A113: =YEAR(C113) -> 1995 | B113: =MONTH(C113) -> 5 | C113: 34820 | D113: 4347586.1 | E113: 4343964.2 | F113: 46.696716 | G113: 46.031582 | H113: 5107655 | I113: 5110287.1 | J113: 46.553356 | K113: 45.922749 | L113: 111
A114: =YEAR(C114) -> 1995 | B114: =MONTH(C114) -> 6 | C114: 34851 | D114: 4389321.9 | E114: 4360309.9 | F114: 46.126671 | G114: 45.905324 | H114: 5118143.6 | I114: 5118954.9 | J114: 45.896009 | K114: 45.923755 | L114: 112
A115: =YEAR(C115) -> 1995 | B115: =MONTH(C115) -> 7 | C115: 34881 | D115: 4409244.5 | E115: 4366455.2 | F115: 46.20902 | G115: 45.938948 | H115: 5116046.9 | I115: 5117346.3 | J115: 45.936448 | K115: 45.915571 | L115: 113
A116: =YEAR(C116) -> 1995 | B116: =MONTH(C116) -> 8 | C116: 34912 | D116: 4421123.2 | E116: 4379520.6 | F116: 46.094094 | G116: 45.800574 | H116: 5126029.8 | I116: 5126681 | J116: 45.805276 | K116: 45.705116 | L116: 114
A117: =YEAR(C117) -> 1995 | B117: =MONTH(C117) -> 9 | C117: 34943 | D117: 4428537.9 | E117: 4393875 | F117: 45.570321 | G117: 45.638098 | H117: 5140995.7 | I117: 5143769.3 | J117: 45.305311 | K117: 45.532044 | L117: 115
A118: =YEAR(C118) -> 1995 | B118: =MONTH(C118) -> 10 | C118: 34973 | D118: 4414623.4 | E118: 4400122.1 | F118: 45.477524 | G118: 45.608434 | H118: 5135425.6 | I118: 5137333.7 | J118: 45.315005 | K118: 45.538904 | L118: 116
A119: =YEAR(C119) -> 1995 | B119: =MONTH(C119) -> 11 | C119: 35004 | D119: 4420418.3 | E119: 4429066.6 | F119: 45.47776 | G119: 45.451231 | H119: 5169144.1 | I119: 5168159.8 | J119: 45.378361 | K119: 45.423161 | L119: 117
A120: =YEAR(C120) -> 1995 | B120: =MONTH(C120) -> 12 | C120: 35034 | D120: 4366314.1 | E120: 4388337.1 | F120: 45.845429 | G120: 45.647613 | H120: 5144227.5 | I120: 5141919.8 | J120: 45.835441 | K120: 45.584959 | L120: 118
A121: =YEAR(C121) -> 1996 | B121: =MONTH(C121) -> 1 | C121: 35065 | D121: 4358650.6 | E121: 4392781.7 | F121: 44.828936 | G121: 45.199521 | H121: 5160197 | I121: 5156144.1 | J121: 45.078935 | K121: 45.345498 | L121: 119
A122: =YEAR(C122) -> 1996 | B122: =MONTH(C122) -> 2 | C122: 35096 | D122: 4356864.7 | E122: 4395540 | F122: 45.092667 | G122: 46.024411 | H122: 5149954.3 | I122: 5144547.8 | J122: 45.403351 | K122: 45.874353 | L122: 120
... A324: =YEAR(C324) -> 2012 | B324: =MONTH(C324) -> 12 | C324: 41244 | D324: 6582462.5 | E324: 6591955.4 | F324: 39.691614 | G324: 39.235313 | H324: 7327746.4 | I324: 7307347 | J324: 39.715302 | K324: 39.232081 | L324: 322

Sheet IPCSAE
A3: Fecha Inicio | B3: 32599 | H3: Fecha Inicio | I3: 32599
A4: Fecha Termino | B4: =EOMONTH(NOW(),-1) -> 43708 | H4: Fecha Termino | I4: 42004
A5: Frecuencia | B5: Q | H5: Frecuencia | I5: Q
A6: Indice de Precios al Consumidor | H6: Indice de Precios al Consumidor
A7: Series Originales | H7: Factores Estacionales
A8: Empalmadas, 2009=100 | H8: Empalmadas, 2009=100
B10: Fecha | C10: IPC | D10: IPCSAE | E10: IPCSAE bienes | F10: IPCSAE servicios | G10: IPCX1 | I10: Fecha | J10: IPC_FE | K10: IPCSAE_FE | L10: IPCSAE bienes_FE | M10: IPCSAE servicios_FE | N10: IPCX1_FE | P10: IPC SA | Q10: IPCSAE SA | R10: IPCSAE bienes SA | S10: IPCSAE servicios SA | T10: IPCX1 SA
B11: Serie o formula | C11: base1'G074.IPC.IND.Z.EP09.C.T | D11: base1'G074.IPCSAE.IND.Z.EP09.C.T | E11: base1'G074.IPCSAE.IND.TRANS.EP09.C.T | F11: base1'G074.IPCSAE.IND.NTRANS.EP09.C.T | G11: base1'G074.IPCX1.IND.Z.EP09.C.T | I11: Serie o formula | J11: base1'G074.IPC.IND.Z.EP09.C.T.X12R.D16 | K11: base1'G074.IPCSAE.IND.Z.EP09.C.T.X12R.D16 | L11: base1'G074.IPCSAE.IND.TRANS.EP09.C.T.X12R.D16 | M11: base1'G074.IPCSAE.IND.NTRANS.EP09.C.T.X12R.D16 | N11: base1'G074.IPCX1.IND.Z.EP09.C.T.X12R.D16
B12: Serie o formula | I12: Serie o formula
B13: fame | I13: fame
B14: =[1]!FAMEData("FAMEDATE", $B$3, $B$4, 0,$B$5, "Down", "Heading", "Normal") -> #NAME? | C14: =[1]!FAMEData(IF(C$13="",C$11,C$13&"("&C$11&")"), $B$3, $B$4, 0,$B$5, "Down", "Heading", "Normal") -> #NAME? | D14: =[1]!FAMEData(IF(D$13="",D$11,D$13&"("&D$11&")"), $B$3, $B$4, 0,$B$5, "Down", "Heading", "Normal") -> #NAME? | E14: =[1]!FAMEData(IF(E$13="",E$11,E$13&"("&E$11&")"), $B$3, $B$4, 0,$B$5, "Down", "Heading", "Normal") -> #NAME? | F14: =[1]!FAMEData(IF(F$13="",F$11,F$13&"("&F$11&")"), $B$3, $B$4, 0,$B$5, "Down", "Heading", "Normal") -> #NAME? | G14: =[1]!FAMEData(IF(G$13="",G$11,G$13&"("&G$11&")"), $B$3, $B$4, 0,$B$5, "Down", "Heading", "Normal") -> #NAME? | I14: =[1]!FAMEData("FAMEDATE", $B$3, $B$4, 0,$B$5, "Down", "Heading", "Normal") -> #NAME? | J14: =[1]!FAMEData(IF(J$13="",J$11,J$13&"("&J$11&")"), $B$3, $B$4, 0,$B$5, "Down", "Heading", "Normal") -> #NAME? | K14: =[1]!FAMEData(IF(K$13="",K$11,K$13&"("&K$11&")"), $B$3, $B$4, 0,$B$5, "Down", "Heading", "Normal") -> #NAME? | L14: =[1]!FAMEData(IF(L$13="",L$11,L$13&"("&L$11&")"), $B$3, $B$4, 0,$B$5, "Down", "Heading", "Normal") -> #NAME? | M14: =[1]!FAMEData(IF(M$13="",M$11,M$13&"("&M$11&")"), $B$3, $B$4, 0,$B$5, "Down", "Heading", "Normal") -> #NAME? | N14: =[1]!FAMEData(IF(N$13="",N$11,N$13&"("&N$11&")"), $B$3, $B$4, 0,$B$5, "Down", "Heading", "Normal") -> #NAME?
B15: 32689 | C15: 23.099144 | D15: 24.066851 | E15: 41.651495 | F15: 17.98604 | G15: 23.31666 | I15: 32689 | J15: 0.99490934 | K15: 1.0066494 | L15: 1.0113833 | M15: 1.004607 | N15: 1.0060425 | P15: =C15/J15 -> 23.217336 | Q15: =D15/K15 -> 23.907877 | R15: =E15/L15 -> 41.182698 | S15: =F15/M15 -> 17.903559 | T15: =G15/N15 -> 23.176615
B16: 32781 | C16: 24.278653 | D16: 25.098168 | E16: 42.530962 | F16: 18.996427 | G16: 24.417276 | I16: 32781 | J16: 0.99803031 | K16: 0.99804638 | L16: 0.99705312 | M16: 0.99949829 | N16: 0.99917368 | P16: =C16/J16 -> 24.326569 | Q16: =D16/K16 -> 25.147296 | R16: =E16/L16 -> 42.656666 | S16: =F16/M16 -> 19.005963 | T16: =G16/N16 -> 24.437469
B17: 32873 | C17: 25.88818 | D17: 26.407535 | E17: 44.431313 | F17: 20.071766 | G17: 25.663891 | I17: 32873 | J17: 1.0107771 | K17: 0.99581328 | L17: 1.0023602 | M17: 0.99235587 | N17: 0.99706262 | P17: =C17/J17 -> 25.612156 | Q17: =D17/K17 -> 26.518561 | R17: =E17/L17 -> 44.326692 | S17: =F17/M17 -> 20.22638 | T17: =G17/N17 -> 25.739497
B18: 32963 | C18: 27.329935 | D18: 28.226595 | E18: 45.863447 | F18: 21.885431 | G18: 27.009741 | I18: 32963 | J18: 0.99938137 | K18: 0.9996659 | L18: 0.98764355 | M18: 1.0049246 | N18: 0.99734254 | P18: =C18/J18 -> 27.346852 | Q18: =D18/K18 -> 28.236028 | R18: =E18/L18 -> 46.437247 | S18: =F18/M18 -> 21.778182 | T18: =G18/N18 -> 27.08171
B19: 33054 | C19: 28.785801 | D19: 30.072803 | E19: 49.275174 | F19: 23.207847 | G19: 28.806828 | I19: 33054 | J19: 0.99424229 | K19: 1.0073594 | L19: 1.0111904 | M19: 1.0056235 | N19: 1.006297 | P19: =C19/J19 -> 28.952501 | Q19: =D19/K19 -> 29.853102 | R19: =E19/L19 -> 48.729867 | S19: =F19/M19 -> 23.078068 | T19: =G19/N19 -> 28.626567
B20: 33146 | C20: 30.735199 | D20: 31.459721 | E20: 51.073178 | F20: 24.403757 | G20: 30.241231 | I20: 33146 | J20: 0.9984882 | K20: 0.99712361 | L20: 0.9971819 | M20: 0.99719604 | N20: 0.99950569 | P20: =C20/J20 -> 30.781735 | Q20: =D20/K20 -> 31.550473 | R20: =E20/L20 -> 51.217514 | S20: =F20/M20 -> 24.472377 | T20: =G20/N20 -> 30.256188
B21: 33238 | C21: 33.401313 | D21: 33.286027 | E21: 53.833069 | F21: 25.874715 | G21: 32.007264 | I21: 33238 | J21: 1.0127685 | K21: 0.9972826 | L21: 1.0028477 | M21: 0.99410694 | N21: 0.99743635 | P21: =C21/J21 -> 32.980206 | Q21: =D21/K21 -> 33.376724 | R21: =E21/L21 -> 53.680205 | S21: =F21/M21 -> 26.0281 | T21: =G21/N21 -> 32.089531
B22: 33328 | C22: 33.916486 | D22: 34.699419 | E22: 55.390087 | F22: 27.166324 | G22: 33.515833 | I22: 33328 | J22: 0.99660405 | K22: 0.99985708 | L22: 0.98870142 | M22: 1.0052589 | N22: 0.99815548 | P22: =C22/J22 -> 34.032058 | Q22: =D22/K22 -> 34.704379 | R22: =E22/L22 -> 56.023068 | S22: =F22/M22 -> 27.024205 | T22: =G22/N22 -> 33.577767
B23: 33419 | C23: 35.620055 | D23: 36.672025 | E23: 59.890404 | F23: 28.352964 | G23: 35.769589 | I23: 33419 | J23: 0.99457307 | K23: 1.0065034 | L23: 1.0100134 | M23: 1.0049861 | N23: 1.0055664 | P23: =C23/J23 -> 35.814418 | Q23: =D23/K23 -> 36.435072 | R23: =E23/L23 -> 59.296644 | S23: =F23/M23 -> 28.212296 | T23: =G23/N23 -> 35.571583
B24: 33511 | C24: 37.467818 | D24: 38.067093 | E24: 61.82855 | F24: 29.521605 | G24: 37.380652 | I24: 33511 | J24: 0.99927964 | K24: 0.99794414 | L24: 0.99725497 | M24: 0.99870823 | N24: 0.99937269 | P24: =C24/J24 -> 37.494828 | Q24: =D24/K24 -> 38.145515 | R24: =E24/L24 -> 61.998738 | S24: =F24/M24 -> 29.55979 | T24: =G24/N24 -> 37.404116
B25: 33603 | C25: 39.442023 | D25: 39.560112 | E25: 64.960348 | F25: 30.492373 | G25: 38.775181 | I25: 33603 | J25: 1.0102212 | K25: 0.99663504 | L25: 1.0037526 | M25: 0.99324518 | N25: 0.99727151 | P25: =C25/J25 -> 39.042957 | Q25: =D25/K25 -> 39.69368 | R25: =E25/L25 -> 64.71749 | S25: =F25/M25 -> 30.699744 | T25: =G25/N25 -> 38.881268
B26: 33694 | C26: 40.250745 | D26: 41.05696 | E26: 66.079483 | F26: 32.000484 | G26: 40.241956 | I26: 33694 | J26: 0.99787118 | K26: 0.99913521 | L26: 0.99055926 | M26: 1.0024577 | N26: 0.99846282 | P26: =C26/J26 -> 40.336615 | Q26: =D26/K26 -> 41.092496 | R26: =E26/L26 -> 66.709268 | S26: =F26/M26 -> 31.922027 | T26: =G26/N26 -> 40.303911
... B109: 41274 | C109: 108.79211 | D109: 104.34936 | E109: 90.181036 | F109: 116.42251 | G109: 103.44011 | I109: 41274 | J109: 1.0016126 | K109: 0.99871145 | L109: 0.9997174 | M109: 0.9978355 | N109: 0.99892638 | P109: =C109/J109 -> 108.61696 | Q109: =D109/K109 -> 104.48399 | R109: =E109/L109 -> 90.206528 | S109: =F109/M109 -> 116.67506 | T109: =G109/N109 -> 103.55129
I110: 41364 | J110: 0.99983027 | K110: 1.0016221 | L110: 1.0017547 | M110: 1.0005471 | N110: 1.0008038
I111: 41455 | J111: 0.9989773 | K111: 1.0008928 | L111: 1.0009316 | M111: 1.0011241 | N111: 1.0005327
I112: 41547 | J112: 0.99978514 | K112: 0.99881867 | L112: 0.99850623 | M112: 0.99983698 | N112: 1.0002611
I113: 41639 | J113: 1.0029687 | K113: 0.99942629 | L113: 0.99963177 | M113: 0.99876089 | N113: 0.99948766
I114: 41729 | J114: 0.99706501 | K114: 1.0008955 | L114: 1.0005334 | M114: 1.0000552 | N114: 0.99994157
I115: 41820 | J115: 0.99855047 | K115: 1.000161 | L115: 1.0003116 | M115: 1.0008892 | N115: 1.0001047
I116: 41912 | J116: 1.0006662 | K116: 0.99956609 | L116: 0.99880799 | M116: 1.0009598 | N116: 1.0001991
I117: 42004 | J117: 1.0018831 | K117: 0.99926413 | L117: 0.99958295 | M117: 0.99930925 | N117: 0.99904709

Sheet PIB_Nominal
A1: Exportar Canasta
A2: Reg | B2: 1 | C2: 2
A3: Descripción series | B3: PIB a precios corrientes serie empalmada | C3: PIB a precios corrientes serie empalmada
A4: Cálculo | B4: Serie Original | C4: Serie Original
A5: 32933 | B5: 2272486 | C5: =+C9*B5/B9 -> 2380661
A6: 33025 | B6: 2435975 | C6: =+C10*B6/B10 -> 2485127.8
A7: 33117 | B7: 2393863 | C7: =+C11*B7/B11 -> 2450244
A8: 33208 | B8: 2649100 | C8: =+C12*B8/B12 -> 2717112.5
A9: 33298 | B9: 2987340 | C9: =+C13*B9/B13 -> 3129543.5
A10: 33390 | B10: 3194308 | C10: =+C14*B10/B14 -> 3258762.4
A11: 33482 | B11: 3134596 | C11: =+C15*B11/B15 -> 3208423
A12: 33573 | B12: 3543079 | C12: =+C16*B12/B16 -> 3634043.3
A13: 33664 | B13: 3899291 | C13: =+C17*B13/B17 -> 4084905.2
A14: 33756 | B14: 3962580 | C14: =+C18*B14/B18 -> 4042536.5
A15: 33848 | B15: 4071912 | C15: =+C19*B15/B19 -> 4167815
A16: 33939 | B16: 4338483 | C16: =+C20*B16/B20 -> 4449868.3
... A56: 37591 | B56: 12225029 | C56: =+C60*B56/B60 -> 12538892
A57: 37681 | B57: 12372622 | C57: 12961584
A58: 37773 | B58: 12911207 | C58: 13171728
A59: 37865 | B59: 12572311 | C59: 12868419
A60: 37956 | B60: 13300275 | C60: 13641744
A61: 38047 | B61: 13463275 | C61: 14302232
A62: 38139 | B62: 14476214 | C62: 14879253
A63: 38231 | B63: 14728838 | C63: 15112053
A64: 38322 | B64: 15634884 | C64: 16252987
A65: 38412 | B65: 15395518 | C65: 16437017
A66: 38504 | B66: 16537704 | C66: 16952650
A67: 38596 | B67: 16670597 | C67: 17080992
A68: 38687 | B68: 17588776 | C68: 18412109
... A91: 40787 | B91: 27929602 | C91: 29078201
A92: 40878 | C92: 31861703
A93: 40969 | C93: 31405318
A94: 41061 | C94: 31623765
A95: 41153 | C95: 31260912
A96: 41244 | C96: 33617704

Sheet EMBI_Chile
B2: EMBI | C2: EMBI Empalmada | D2: EMBI ex Codelco | E2: Spread | F2: EMBI ex Codelco | G2: EMBI BASE 7 | J2: Date | K2: F019.SPS.PBP.91.M
A3: 1986T1 | B3: =[2]data_ipom!W14 -> 0 | C3: =F3*C4/F4 -> 213.7201 | D3: =[2]data_ipom!X14 -> 0 | E3: 2 | F3: =+E3*100 -> 200 | J3: 36281 | K3: 192
A4: 1986T2 | B4: =[2]data_ipom!W15 -> 0 | C4: =F4*C5/F5 -> 234.91045 | D4: =[2]data_ipom!X15 -> 0 | E4: 2.1983 | F4: =+E4*100 -> 219.83 | J4: 36312 | K4: 188
A5: 1986T3 | B5: =[2]data_ipom!W16 -> 224.665 | C5: =F5*C6/F6 -> 240.07713 | D5: =[2]data_ipom!X16 -> 224.665 | E5: 2.24665 | F5: =+E5*100 -> 224.665 | J5: 36342 | K5: 185 | L5: 1
A6: 1986T4 | B6: =[2]data_ipom!W17 -> 205 | C6: =F6*C7/F7 -> 219.0631 | D6: =[2]data_ipom!X17 -> 205 | E6: 2.05 | F6: =+E6*100 -> 205 | J6: 36373 | K6: 191 | L6: 2
A7: 1987T1 | B7: =[2]data_ipom!W18 -> 160.665 | C7: =F7*C8/F8 -> 171.6867 | D7: =[2]data_ipom!X18 -> 160.665 | E7: 1.60665 | F7: =+E7*100 -> 160.665 | J7: 36404 | K7: 187 | L7: 3
A8: 1987T2 | B8: =[2]data_ipom!W19 -> 172.165 | C8: =F8*C9/F9 -> 183.9756 | D8: =[2]data_ipom!X19 -> 172.165 | E8: 1.72165 | F8: =+E8*100 -> 172.165 | J8: 36434 | K8: 159 | L8: 4
A9: 1987T3 | B9: =[2]data_ipom!W20 -> 196.665 | C9: =F9*C10/F10 -> 210.15632 | D9: =[2]data_ipom!X20 -> 196.665 | E9: 1.96665 | F9: =+E9*100 -> 196.665 | J9: 36465 | K9: 156 | L9: 5
A10: 1987T4 | B10: =[2]data_ipom!W21 -> 107.665 | C10: =F10*C11/F11 -> 115.05087 | D10: =[2]data_ipom!X21 -> 107.665 | E10: 1.07665 | F10: =+E10*100 -> 107.665 | J10: 36495 | K10: 145 | L10: 6
A11: 1988T1 | B11: =[2]data_ipom!W22 -> 56 | C11: =F11*C12/F12 -> 59.841627 | D11: =[2]data_ipom!X22 -> 56 | E11: 0.56 | F11: =+E11*100 -> 56 | J11: 36526 | K11: 150 | L11: 7
A12: 1988T2 | B12: =[2]data_ipom!W23 -> 52.5 | C12: =F12*C13/F13 -> 56.101526 | D12: =[2]data_ipom!X23 -> 52.5 | E12: 0.525 | F12: =+E12*100 -> 52.5 | J12: 36557 | K12: 161 | L12: 8
A13: 1988T3 | B13: =[2]data_ipom!W24 -> 52.165 | C13: =F13*C14/F14 -> 55.743544 | D13: =[2]data_ipom!X24 -> 52.165 | E13: 0.52165 | F13: =+E13*100 -> 52.165 | J13: 36586 | K13: 172 | L13: 9
A14: 1988T4 | B14: =[2]data_ipom!W25 -> 67.5 | C14: =F14*C15/F15 -> 72.130533 | D14: =[2]data_ipom!X25 -> 67.5 | E14: 0.675 | F14: =+E14*100 -> 67.5 | J14: 36617 | K14: 200 | L14: 10
A15: 1989T1 | B15: =[2]data_ipom!W26 -> 66.835 | C15: =F15*C16/F16 -> 71.419914 | D15: =[2]data_ipom!X26 -> 66.835 | E15: 0.66835 | F15: =+E15*100 -> 66.835 | J15: 36647 | K15: 186 | L15: 11
A16: 1989T2 | B16: =[2]data_ipom!W27 -> 63.165 | C16: =F16*C17/F17 -> 67.49815 | D16: =[2]data_ipom!X27 -> 63.165 | E16: 0.63165 | F16: =+E16*100 -> 63.165 | J16: 36678 | K16: 220 | L16: 12
... A55: 1999T1 | B55: =[2]data_ipom!W66 -> 195.83333 | C55: =F55*C56/F56 -> 209.2676 | D55: =[2]data_ipom!X66 -> 195.83333 | E55: 1.9583333 | F55: =+E55*100 -> 195.83333 | J55: 37865 | K55: 108 | L55: 51
A56: 1999T2 | B56: =[2]data_ipom!W67 -> 190.03279 | C56: =B56 -> 190.03279 | D56: =[2]data_ipom!X67 -> 177.83333 | E56: 1.7783333 | F56: =+E56*100 -> 177.83333 | J56: 37895 | K56: 97 | L56: 52
A57: 1999T3 | B57: =[2]data_ipom!W68 -> 187.67391 | C57: =B57 -> 187.67391 | D57: =[2]data_ipom!X68 -> 161 | E57: 1.61 | F57: =+E57*100 -> 161 | G57: =AVERAGE(OFFSET($K$5,(L5-1)*3,0,3,1)) -> 187.66667 | H57: =B57-G57 -> 0.0072463768 | J57: 37926 | K57: 87 | L57: 53 | N57: =[1]!FAMEData(K2, "1999q3", "2013", 0,"Quarterly", "Down", "No Heading", "Normal") -> #NAME? | O57: =N57/B57 -> #NAME?
A58: 1999T4 | B58: =[2]data_ipom!W69 -> 153.30435 | C58: =B58 -> 153.30435 | D58: =[2]data_ipom!X69 -> 153 | E58: 1.53 | F58: =+E58*100 -> 153 | G58: =AVERAGE(OFFSET($K$5,(L6-1)*3,0,3,1)) -> 153.33333 | H58: =B58-G58 -> -0.028985507 | J58: 37956 | K58: 86 | L58: 54 | N58: 153.30435 | O58: =N58/B58 -> 1
A59: 2000T1 | B59: =[2]data_ipom!W70 -> 161 | C59: =B59 -> 161 | D59: =[2]data_ipom!X70 -> 161.08144 | E59: 1.6479581 | F59: =+E59*100 -> 164.79581 | G59: =AVERAGE(OFFSET($K$5,(L7-1)*3,0,3,1)) -> 161 | H59: =B59-G59 -> 0 | J59: 37987 | K59: 88 | L59: 55 | N59: 161 | O59: =N59/B59 -> 1
A60: 2000T2 | B60: =[2]data_ipom!W71 -> 201.82418 | C60: =B60 -> 201.82418 | D60: =[2]data_ipom!X71 -> 201.74394 | E60: 2.1809634 | F60: =+E60*100 -> 218.09634 | G60: =AVERAGE(OFFSET($K$5,(L8-1)*3,0,3,1)) -> 202 | H60: =B60-G60 -> -0.17582418 | J60: 38018 | K60: 93 | L60: 56 | N60: 201.82418 | O60: =N60/B60 -> 1
A61: 2000T3 | B61: =[2]data_ipom!W72 -> 202.44565 | C61: =B61 -> 202.44565 | D61: =[2]data_ipom!X72 -> 202.61422 | E61: 1.93 | F61: =+E61*100 -> 193 | G61: =AVERAGE(OFFSET($K$5,(L9-1)*3,0,3,1)) -> 202.33333 | H61: =B61-G61 -> 0.11231884 | J61: 38047 | K61: 93 | L61: 57 | N61: 202.44565 | O61: =N61/B61 -> 1
A62: 2000T4 | B62: =[2]data_ipom!W73 -> 223.61957 | C62: =B62 -> 223.61957 | D62: =[2]data_ipom!X73 -> 223.76912 | E62: 2.27 | F62: =+E62*100 -> 227 | G62: =AVERAGE(OFFSET($K$5,(L10-1)*3,0,3,1)) -> 223.66667 | H62: =B62-G62 -> -0.047101449 | J62: 38078 | K62: 86 | L62: 58 | N62: 223.61957 | O62: =N62/B62 -> 1
A63: 2001T1 | B63: =[2]data_ipom!W74 -> 196.92222 | C63: =B63 -> 196.92222 | D63: =[2]data_ipom!X74 -> 196.52069 | E63: 1.93 | F63: =+E63*100 -> 193 | G63: =AVERAGE(OFFSET($K$5,(L11-1)*3,0,3,1)) -> 196.66667 | H63: =B63-G63 -> 0.25555556 | J63: 38108 | K63: 98 | L63: 59 | N63: 196.92222 | O63: =N63/B63 -> 1
A64: 2001T2 | B64: =[2]data_ipom!W75 -> 177.68132 | C64: =B64 -> 177.68132 | D64: =[2]data_ipom!X75 -> 178.45549 | E64: 1.91 | F64: =+E64*100 -> 191 | G64: =AVERAGE(OFFSET($K$5,(L12-1)*3,0,3,1)) -> 177.66667 | H64: =B64-G64 -> 0.014652015 | J64: 38139 | K64: 86 | L64: 60 | N64: 177.68132 | O64: =N64/B64 -> 1
A65: 2001T3 | B65: =[2]data_ipom!W76 -> 192.3913 | C65: =B65 -> 192.3913 | D65: =[2]data_ipom!X76 -> 191.80837 | E65: 1.75 | F65: =+E65*100 -> 175 | G65: =AVERAGE(OFFSET($K$5,(L13-1)*3,0,3,1)) -> 192.66667 | H65: =B65-G65 -> -0.27536232 | J65: 38169 | K65: 85 | L65: 61 | N65: 192.3913 | O65: =N65/B65 -> 1
A66: 2001T4 | B66: =[2]data_ipom!W77 -> 201.98913 | C66: =B66 -> 201.98913 | D66: =[2]data_ipom!X77 -> 201.9963 | E66: 1.67 | F66: =+E66*100 -> 167 | G66: =AVERAGE(OFFSET($K$5,(L14-1)*3,0,3,1)) -> 202 | H66: =B66-G66 -> -0.010869565 | J66: 38200 | K66: 73 | L66: 62 | N66: 201.98913 | O66: =N66/B66 -> 1
A67: 2002T1 | B67: =[2]data_ipom!W78 -> 159.38889 | C67: =B67 -> 159.38889 | D67: =[2]data_ipom!X78 -> 159.39451 | E67: 1.62 | F67: =+E67*100 -> 162 | G67: =AVERAGE(OFFSET($K$5,(L15-1)*3,0,3,1)) -> 159.66667 | H67: =B67-G67 -> -0.27777778 | J67: 38231 | K67: 72 | L67: 63 | N67: 159.38889 | O67: =N67/B67 -> 1
A68: 2002T2 | B68: =[2]data_ipom!W79 -> 144.61538 | C68: =B68 -> 144.61538 | D68: =[2]data_ipom!X79 -> 144.55501 | E68: 1.6 | F68: =+E68*100 -> 160 | G68: =AVERAGE(OFFSET($K$5,(L16-1)*3,0,3,1)) -> 144.66667 | H68: =B68-G68 -> -0.051282051 | J68: 38261 | K68: 78 | L68: 64 | N68: 144.61538 | O68: =N68/B68 -> 1
A69: 2002T3 | B69: =[2]data_ipom!W80 -> 204.71739 | C69: =B69 -> 204.71739 | D69: =[2]data_ipom!X80 -> 204.62626 | E69: 1.58 | F69: =+E69*100 -> 158 | G69: =AVERAGE(OFFSET($K$5,(L17-1)*3,0,3,1)) -> 204.66667 | H69: =B69-G69 -> 0.050724638 | J69: 38292 | K69: 73 | L69: 65 | N69: 204.71739 | O69: =N69/B69 -> 1
... A95: 2009T1 | B95: =[2]data_ipom!W106 -> 357.22222 | C95: =B95 -> 357.22222 | D95: =[2]data_ipom!X106 -> 204.22437 | E95: 1.6673756 | F95: =+E95*100 -> 166.73756 | G95: =AVERAGE(OFFSET($K$5,(L43-1)*3,0,3,1)) -> 357.66667 | H95: =B95-G95 -> -0.44444444 | J95: 39083 | K95: 81 | L95: 91 | N95: 357.22222 | O95: =N95/B95 -> 1
A96: 2009T2 | B96: =[2]data_ipom!W107 -> 241.41758 | C96: =B96 -> 241.41758 | D96: =[2]data_ipom!X107 -> 149.99875 | G96: =AVERAGE(OFFSET($K$5,(L44-1)*3,0,3,1)) -> 241.33333 | H96: =B96-G96 -> 0.084249084 | J96: 39114 | K96: 80 | L96: 92 | N96: 241.41758 | O96: =N96/B96 -> 1
A97: 2009T3 | B97: =[2]data_ipom!W108 -> 146.70652 | C97: =B97 -> 146.70652 | D97: =[2]data_ipom!X108 -> 74.605603 | G97: =AVERAGE(OFFSET($K$5,(L45-1)*3,0,3,1)) -> 146.66667 | H97: =B97-G97 -> 0.039855072 | J97: 39142 | K97: 86 | L97: 93 | N97: 146.70652 | O97: =N97/B97 -> 1
A98: 2009T4 | B98: =[2]data_ipom!W109 -> 126.29348 | C98: =B98 -> 126.29348 | D98: =[2]data_ipom!X109 -> 68.09663 | G98: =AVERAGE(OFFSET($K$5,(L46-1)*3,0,3,1)) -> 126.33333 | H98: =B98-G98 -> -0.039855072 | J98: 39173 | K98: 82 | L98: 94 | N98: 126.29348 | O98: =N98/B98 -> 1
A99: 2010T1 | B99: =[2]data_ipom!W110 -> 122.35556 | C99: =B99 -> 122.35556 | D99: =[2]data_ipom!X110 -> 73.306297 | G99: =AVERAGE(OFFSET($K$5,(L47-1)*3,0,3,1)) -> 122.66667 | H99: =B99-G99 -> -0.31111111 | J99: 39203 | K99: 80 | L99: 95 | N99: 122.35556 | O99: =N99/B99 -> 1
A100: 2010T2 | B100: =[2]data_ipom!W111 -> 135.05495 | C100: =B100 -> 135.05495 | D100: =[2]data_ipom!X111 -> 85.694232 | G100: =AVERAGE(OFFSET($K$5,(L48-1)*3,0,3,1)) -> 135 | H100: =B100-G100 -> 0.054945055 | J100: 39234 | K100: 80 | L100: 96 | N100: 135.05495 | O100: =N100/B100 -> 1
A101: 2010T3 | B101: =[2]data_ipom!W112 -> 134.68478 | C101: =B101 -> 134.68478 | D101: =[2]data_ipom!X112 -> 85.350124 | G101: =AVERAGE(OFFSET($K$5,(L49-1)*3,0,3,1)) -> 134.66667 | H101: =B101-G101 -> 0.018115942 | J101: 39264 | K101: 90 | L101: 97 | N101: 134.68478 | O101: =N101/B101 -> 1
A102: 2010T4 | B102: =[2]data_ipom!W113 -> 124.33696 | C102: =B102 -> 124.33696 | D102: =[2]data_ipom!X113 -> 75.449363 | G102: =AVERAGE(OFFSET($K$5,(L50-1)*3,0,3,1)) -> 124.33333 | H102: =B102-G102 -> 0.0036231884 | J102: 39295 | K102: 108 | L102: 98 | N102: 124.33696 | O102: =N102/B102 -> 1
A103: 2011T1 | B103: =[2]data_ipom!W114 -> 114.68889 | C103: =B103 -> 114.68889 | D103: =[2]data_ipom!X114 -> 75.639479 | G103: =AVERAGE(OFFSET($K$5,(L51-1)*3,0,3,1)) -> 114.66667 | H103: =B103-G103 -> 0.022222222 | J103: 39326 | K103: 121 | L103: 99 | N103: 114.68889 | O103: =N103/B103 -> 1
A104: 2011T2 | B104: =[2]data_ipom!W115 -> 127.65934 | C104: =B104 -> 127.65934 | D104: =[2]data_ipom!X115 -> 82.544277 | G104: =AVERAGE(OFFSET($K$5,(L52-1)*3,0,3,1)) -> 127.66667 | H104: =B104-G104 -> -0.0073260073 | J104: 39356 | K104: 117 | L104: 100 | N104: 127.65934 | O104: =N104/B104 -> 1
...

Sheet Balanza_Comercial
B1: fuente: bcentral.cl
A2: Nombre Largo | B2: Exportaciones de Bienes por Trimestre | C2: Total de importación de bienes (cif) | D2: Total de importación de bienes (fob) | E2: Exportaciones de bienes (FOB) | F2: Importaciones Totales (CIF) | G2: Exportaciones Reales | H2: Importaciones Reales | I2: Balanza Comercial Nominal | J2: Balanza Comercial Real
A3: Unidad | B3: Mill. US$ | C3: Mill. US$ | D3: Mill. US$ | E3: Mill. US$ | F3: Mill. US$ | G3: Mill. $ 08 | H3: Mill. $ 08 | I3: Mill. US $ | J3: Mill. $ 08
A4: Origen datos | B4: bcentral.cl | C4: bcentral.cl | D4: bcentral.cl | E4: DAC | F4: DAC | G4: CC.NN | H4: CC.NN | I4: CC.NN. | J4: CC.NN
A5: Acceso | B5: Público | C5: Público | D5: Público | E5: Público | F5: Público | G5: Público | H5: Público | I5: Pública | J5: Público
A6: Fecha actualización | B6: 41319 | C6: 41319 | D6: 41319 | E6: 41319 | F6: 41319 | G6: 41319 | H6: 41319 | I6: 41319 | J6: 41319
A7: Ult. Dato Efectivo | B7: 2012T4 | C7: 2012T4 | D7: 2012T4 | E7: 2012T4 | F7: 2012T4 | G7: 2012T4 | H7: 2012T4 | I7: 2012T4 | J7: 2012T4
A8: 1986T1 | B8: =G8*B9/G9 -> 1310.3364 | C8: =H8*C9/H9 -> 791.63475 | G8: =[3]Originales!M12 -> 1896676.5 | H8: =[3]Originales!N12 -> 768338.27 | I8: =B8-C8 -> 518.70168 | J8: =G8-H8 -> 1128338.3
A9: 1986T2 | B9: =G9*B10/G10 -> 1231.2845 | C9: =H9*C10/H10 -> 805.18262 | G9: =[3]Originales!M13 -> 1782251 | H9: =[3]Originales!N13 -> 781487.45 | I9: =B9-C9 -> 426.10185 | J9: =G9-H9 -> 1000763.5
A10: 1986T3 | B10: =G10*B11/G11 -> 1094.4157 | C10: =H10*C11/H11 -> 911.9106 | G10: =[3]Originales!M14 -> 1584137.1 | H10: =[3]Originales!N14 -> 885074.61 | I10: =B10-C10 -> 182.50509 | J10: =G10-H10 -> 699062.52
A11: 1986T4 | B11: =G11*B12/G12 -> 1240.1651 | C11: =H11*C12/H12 -> 929.75667 | G11: =[3]Originales!M15 -> 1795105.5 | H11: =[3]Originales!N15 -> 902395.49 | I11: =B11-C11 -> 310.40844 | J11: =G11-H11 -> 892709.96
A12: 1987T1 | B12: =G12*B13/G13 -> 1505.1514 | C12: =H12*C13/H13 -> 1017.8823 | G12: =[3]Originales!M16 -> 2178666 | H12: =[3]Originales!N16 -> 987927.75 | I12: =B12-C12 -> 487.2691 | J12: =G12-H12 -> 1190738.2
A13: 1987T2 | B13: =G13*B14/G14 -> 1336.0283 | C13: =H13*C14/H14 -> 999.16291 | G13: =[3]Originales!M17 -> 1933864.9 | H13: =[3]Originales!N17 -> 969759.23 | I13: =B13-C13 -> 336.86543 | J13: =G13-H13 -> 964105.67
A14: 1987T3 | B14: =G14*B15/G15 -> 1128.6698 | C14: =H14*C15/H15 -> 1055.5741 | G14: =[3]Originales!M18 -> 1633719 | H14: =[3]Originales!N18 -> 1024510.3 | I14: =B14-C14 -> 73.09576 | J14: =G14-H14 -> 609208.75
A15: 1987T4 | B15: =G15*B16/G16 -> 1235.0212 | C15: =H15*C16/H16 -> 1005.7601 | G15: =[3]Originales!M19 -> 1787659.8 | H15: =[3]Originales!N19 -> 976162.24 | I15: =B15-C15 -> 229.26114 | J15: =G15-H15 -> 811497.56
A16: 1988T1 | B16: =G16*B17/G17 -> 1583.0845 | C16: =H16*C17/H17 -> 1116.9117 | G16: =[3]Originales!M20 -> 2291472 | H16: =[3]Originales!N20 -> 1084042.8 | I16: =B16-C16 -> 466.17283 | J16: =G16-H16 -> 1207429.2
A17: 1988T2 | B17: =G17*B18/G18 -> 1463.1005 | C17: =H17*C18/H18 -> 1062.4343 | G17: =[3]Originales!M21 -> 2117798.4 | H17: =[3]Originales!N21 -> 1031168.7 | I17: =B17-C17 -> 400.66617 | J17: =G17-H17 -> 1086629.7
A18: 1988T3 | B18: =G18*B19/G19 -> 1287.7687 | C18: =H18*C19/H19 -> 1162.6795 | G18: =[3]Originales!M22 -> 1864010.4 | H18: =[3]Originales!N22 -> 1128463.8 | I18: =B18-C18 -> 125.08919 | J18: =G18-H18 -> 735546.58
A19: 1988T4 | B19: =G19*B20/G20 -> 1472.3764 | C19: =H19*C20/H20 -> 1258.1125 | G19: =[3]Originales!M23 -> 2131225 | H19: =[3]Originales!N23 -> 1221088.4 | I19: =B19-C19 -> 214.2639 | J19: =G19-H19 -> 910136.65
... A75: 2002T4 | B75: =G75*B76/G76 -> 4926.1392 | C75: =H75*C76/H76 -> 4534.8859 | G75: =[3]Originales!M79 -> 7130453.3 | H75: =[3]Originales!N79 -> 4401431.9 | I75: =B75-C75 -> 391.25326 | J75: =G75-H75 -> 2729021.4
A76: 2003T1 | B76: 5193.575 | C76: 4518.0658 | D76: 4200.1962 | E76: =[4]Expo!C12 -> 5193.575 | F76: =[4]Impo!C12 -> 4518.0658 | G76: =[3]Originales!M80 -> 7517559.4 | H76: =[3]Originales!N80 -> 4385106.7 | I76: =B76-C76 -> 675.50923 | J76: =G76-H76 -> 3132452.7
A77: 2003T2 | B77: 5307.8952 | C77: 4805.9948 | D77: 4461.7284 | E77: =[4]Expo!C13 -> 5307.8952 | F77: =[4]Impo!C13 -> 4805.9948 | G77: =[3]Originales!M81 -> 7392756.8 | H77: =[3]Originales!N81 -> 4725916.3 | I77: =B77-C77 -> 501.90042 | J77: =G77-H77 -> 2666840.5
A78: 2003T3 | B78: 5182.2164 | C78: 4894.6989 | D78: 4541.7479 | E78: =[4]Expo!C14 -> 5182.2164 | F78: =[4]Impo!C14 -> 4894.6989 | G78: =[3]Originales!M82 -> 7278440.4 | H78: =[3]Originales!N82 -> 4790481.8 | I78: =B78-C78 -> 287.51744 | J78: =G78-H78 -> 2487958.6
A79: 2003T4 | B79: 5967.2203 | C79: 5045.3656 | D79: 4681.8457 | E79: =[4]Expo!C15 -> 5967.2203 | F79: =[4]Impo!C15 -> 5045.3656 | G79: =[3]Originales!M83 -> 7510067.5 | H79: =[3]Originales!N83 -> 4991522.6 | I79: =B79-C79 -> 921.85474 | J79: =G79-H79 -> 2518545
A80: 2004T1 | B80: 7685.2243 | C80: 5381.1762 | D80: 4966.5554 | E80: =[4]Expo!C16 -> 7685.2243 | F80: =[4]Impo!C16 -> 5381.1762 | G80: =[3]Originales!M84 -> 8349255.1 | H80: =[3]Originales!N84 -> 4973381.2 | I80: =B80-C80 -> 2304.048 | J80: =G80-H80 -> 3375873.9
A81: 2004T2 | B81: 7974.575 | C81: 5707.8526 | D81: 5299.3152 | E81: =[4]Expo!C17 -> 7974.575 | F81: =[4]Impo!C17 -> 5707.8526 | G81: =[3]Originales!M85 -> 8319262 | H81: =[3]Originales!N85 -> 5360876.8 | I81: =B81-C81 -> 2266.7224 | J81: =G81-H81 -> 2958385.2
A82: 2004T3 | B82: 8426.19 | C82: 6626.6082 | D82: 6122.6989 | E82: =[4]Expo!C18 -> 8426.19 | F82: =[4]Impo!C18 -> 6626.6082 | G82: =[3]Originales!M86 -> 8489441.4 | H82: =[3]Originales!N86 -> 5917325.8 | I82: =B82-C82 -> 1799.5818 | J82: =G82-H82 -> 2572115.6
A83: 2004T4 | B83: 8939.4177 | C83: 7011.3098 | D83: 6480.7238 | E83: =[4]Expo!C19 -> 8939.4177 | F83: =[4]Impo!C19 -> 7011.3098 | G83: =[3]Originales!M87 -> 8703018.5 | H83: =[3]Originales!N87 -> 6099485.6 | I83: =B83-C83 -> 1928.1079 | J83: =G83-H83 -> 2603532.9
A84: 2005T1 | B84: 9430.7375 | C84: 7254.1994 | D84: 6723.5241 | E84: =[4]Expo!C20 -> 9430.7375 | F84: =[4]Impo!C20 -> 7254.1994 | G84: =[3]Originales!M88 -> 8470058.2 | H84: =[3]Originales!N88 -> 5920375 | I84: =B84-C84 -> 2176.5381 | J84: =G84-H84 -> 2549683.2
A85: 2005T2 | B85: 10257.305 | C85: 7913.464 | D85: 7369.7329 | E85: =[4]Expo!C21 -> 10257.305 | F85: =[4]Impo!C21 -> 7913.464 | G85: =[3]Originales!M89 -> 8715657.7 | H85: =[3]Originales!N89 -> 6383443.7 | I85: =B85-C85 -> 2343.8409 | J85: =G85-H85 -> 2332214
A86: 2005T3 | B86: 10275.302 | C86: 8747.8717 | D86: 8168.4437 | E86: =[4]Expo!C22 -> 10275.302 | F86: =[4]Impo!C22 -> 8747.8717 | G86: =[3]Originales!M90 -> 8590562.1 | H86: =[3]Originales!N90 -> 6893546.9 | I86: =B86-C86 -> 1527.43 | J86: =G86-H86 -> 1697015.3
A87: 2005T4 | B87: 12010.648 | C87: 9009.9731 | D87: 8402.8284 | E87: =[4]Expo!C23 -> 12010.648 | F87: =[4]Impo!C23 -> 9009.9731 | G87: =[3]Originales!M91 -> 9043925.5 | H87: =[3]Originales!N91 -> 7010330.4 | I87: =B87-C87 -> 3000.6754 | J87: =G87-H87 -> 2033595.2
... A115: 2012T4 | B115: 21703.293 | C115: 21257.371 | D115: 20046.397 | E115: =[4]Expo!C51 -> 20451.694 | F115: =[4]Impo!C51 -> 22146.749 | G115: =[3]Originales!M119 -> 10820081 | H115: =[3]Originales!N119 -> 12730946 | I115: =B115-C115 -> 445.92171 | J115: =G115-H115 -> -1910864.6

Sheet Cuenta_Corriente
C1: Balanza de pagos resumen (millones de dólares) 2003-2012q3 | K1: Balanza de pagos resumen (millones de dólares) 1996-2011 | N1: Datos Modelo Macro | X1: Balanza de Pagos, 1973-1995 (Millones de dólares) | Z1: Balanza de pagos resumen 1996-2011 (millones de dólares) | AB1: Balanza de pagos resumen (millones de dólares)
B2: CC Empalmada | C2: 1. Cuenta corriente | D2: 2. Bienes (X-M) | E2: 3. Exportaciones | F2: 4. Importaciones (FOB) | G2: 5. Servicios | H2: 6. Renta (ingreso primario) | I2: 7. Transferencias corrientes (ingreso secundario) | J2: Construccion Cuenta Corriente | K2: 1. Cuenta corriente | L2: CC - Método Linear Matcgh Last - trimestralizar serie anual | O2: Cuenta Corriente | P2: Balanza Comercial | Q2: Balance Servicios | R2: Rentas | S2: Transferencias | X2: Periodo | Y2: Cuenta Corriente Empalmada | Z2: 1. Cuenta corriente | AA2: 1. Cuenta corriente | AB2: 1. Cuenta corriente
A3: 1986T1 | B3: =B4*L3/L4 -> -263.23384 | L3: -1446.2017 | N3: 2008 | O3: 1307.1366 | P3: 6072.4574 | Q3: -176.1973 | R3: -5096.8235 | S3: 507.7 | T3: =+P3+Q3+R3+S3 -> 1307.1366 | X3: 26665 | Y3: =Y4*Z3/Z4 -> -312.77288 | Z3: -293.6
A4: 1986T2 | B4: =B5*L4/L5 -> -252.48189 | L4: -1387.1307 | N4: 2008.25 | O4: -881.11661 | P4: 2832.9158 | Q4: -370.82882 | R4: -4600.4036 | S4: 1257.2 | T4: =+P4+Q4+R4+S4 -> -881.11661 | X4: 27030 | Y4: =Y5*Z4/Z5 -> -224.56581 | Z4: -210.8
A5: 1986T3 | B5: =B6*L5/L6 -> -241.72993 | L5: -1328.0596 | N5: 2008.5 | O5: -3350.0903 | P5: -1457.515 | Q5: -398.29125 | R5: -2222.884 | S5: 728.6 | T5: =+P5+Q5+R5+S5 -> -3350.0903 | X5: 27395 | Y5: =Y6*Z5/Z6 -> -523.80934 | Z5: -491.7
A6: 1986T4 | B6: =B7*L6/L7 -> -230.97798 | L6: -1268.9886 | N6: 2008.75 | O6: -2875.9473 | P6: -1373.7181 | Q6: -262.35903 | R6: -1676.1701 | S6: 436.3 | T6: =+P6+Q6+R6+S6 -> -2875.9473 | X6: 27760 | Y6: =Y7*Z6/Z7 -> 157.34521 | Z6: 147.7
A7: 1987T1 | B7: =B8*L7/L8 -> -208.88751 | L7: -1147.624 | N7: 2009 | O7: 953.4918 | P7: 2541.4623 | Q7: -311.57506 | R7: -1539.5954 | S7: 263.2 | T7: =+P7+Q7+R7+S7 -> 953.4918 | X7: 28126 | Y7: =Y8*Z7/Z8 -> -586.98179 | Z7: -551
A8: 1987T2 | B8: =B9*L8/L9 -> -186.79704 | L8: -1026.2594 | N8: 2009.25 | O8: 1812.5861 | P8: 4137.798 | Q8: -576.42855 | R8: -2472.6833 | S8: 723.9 | T8: =+P8+Q8+R8+S8 -> 1812.5861 | X8: 28491 | Y8: =Y9*Z8/Z9 -> -1158.9428 | Z8: -1087.9
A9: 1987T3 | B9: =B10*L9/L10 -> -164.70657 | L9: -904.89475 | N9: 2009.5 | O9: 305.81884 | P9: 3585.8413 | Q9: -683.39954 | R9: -2830.9229 | S9: 234.3 | T9: =+P9+Q9+R9+S9 -> 305.81884 | X9: 28856 | Y9: =Y10*Z9/Z10 -> -1267.071 | Z9: -1189.4
A10: 1987T4 | B10: =B11*L10/L11 -> -142.6161 | L10: -783.53014 | N10: 2009.75 | O10: 446.10735 | P10: 5094.9308 | Q10: -439.03987 | R10: -4551.4836 | S10: 341.7 | T10: =+P10+Q10+R10+S10 -> 446.10735 | X10: 29221 | Y10: =Y11*Z10/Z11 -> -2099.2855 | Z10: -1970.6
A11: 1988T1 | B11: =B12*L11/L12 -> -118.16971 | L11: -649.2221 | N11: 2010 | O11: 2161.0674 | P11: 3864.1278 | Q11: -174.82762 | R11: -3185.2498 | S11: 1657.0169 | T11: =+P11+Q11+R11+S11 -> 2161.0674 | X11: 29587 | Y11: =Y12*Z11/Z12 -> -5041.6516 | Z11: -4732.6
A12: 1988T2 | B12: =B13*L12/L13 -> -93.723309 | L12: -514.91406 | N12: 2010.25 | O12: 793.62469 | P12: 3056.9269 | Q12: -457.79172 | R12: -3159.9194 | S12: 1354.4089 | T12: =+P12+Q12+R12+S12 -> 793.62469 | X12: 29952 | Y12: =Y13*Z12/Z13 -> -2454.6705 | Z12: -2304.2
A13: 1988T3 | B13: =B14*L13/L14 -> -69.276912 | L13: -380.60602 | N13: 2010.5 | O13: -757.75826 | P13: 3503.792 | Q13: -628.14095 | R13: -4151.0022 | S13: 517.59288 | T13: =+P13+Q13+R13+S13 -> -757.75826 | X13: 30317 | Y13: =Y14*Z13/Z14 -> -1190.2627 | Z13: -1117.3
A14: 1988T4 | B14: =B15*L14/L15 -> -44.830514 | L14: -246.29799 | N14: 2010.75 | O14: 1071.6331 | P14: 4899.6251 | Q14: -545.06671 | R14: -4269.06 | S14: 986.13466 | T14: =+P14+Q14+R14+S14 -> 1071.6331 | X14: 30682 | Y14: =Y15*Z14/Z15 -> -2248.3214 | Z14: -2110.5
... A22: 1990T4 | B22: =B23*L22/L23 -> -94.004469 | L22: -516.45875 | N22: 2012.75 | O22: -3614.7742 | P22: -230.43876 | Q22: -428.79477 | R22: -3832.9009 | S22: 877.36032 | T22: =+P22+Q22+R22+S22 -> -3614.7742 | X22: 33604 | Y22: =Y23*Z22/Z23 -> -1020.7731 | Z22: -958.2
A23: 1991T1 | B23: =B24*L23/L24 -> -75.283076 | L23: -413.60378 | X23: 33970 | Y23: =Y24*Z23/Z24 -> -2720.1439 | Z23: -2553.4
A24: 1991T2 | B24: =B25*L24/L25 -> -56.561683 | L24: -310.7488 | X24: 34335 | Y24: =Y25*Z24/Z25 -> -1688.8244 | Z24: -1585.3
A25: 1991T3 | B25: =B26*L25/L26 -> -37.840289 | L25: -207.89382 | X25: 34700 | Y25: =Y26*Z25/Z26 -> -1432.9387 | Z25: -1345.1
A26: 1991T4 | B26: =B27*L26/L27 -> -19.118896 | L26: -105.03885 | X26: 35065 | Y26: =Y27*AA26/AA27 -> -3284.0087 | Z26: =AA26 -> -3082.7 | AA26: -3082.7
A27: 1992T1 | B27: =B28*L27/L28 -> -60.788781 | L27: -333.9724 | X27: 35431 | Y27: =Y28*AA27/AA28 -> -3899.221 | AA27: -3660.2
A28: 1992T2 | B28: =B29*L28/L29 -> -102.45867 | L28: -562.90595 | X28: 35796 | Y28: =Y29*AA28/AA29 -> -4174.2821 | AA28: -3918.4
A29: 1992T3 | B29: =B30*L29/L30 -> -144.12855 | L29: -791.8395 | X29: 36161 | Y29: =Y30*AA29/AA30 -> 105.99762 | AA29: 99.5
A30: 1992T4 | B30: =B31*L30/L31 -> -185.79844 | L30: -1020.7731 | X30: 36526 | Y30: =Y31*AA30/AA31 -> -956.00265 | AA30: -897.4
A31: 1993T1 | B31: =B32*L31/L32 -> -263.1272 | L31: -1445.6158 | X31: 36892 | Y31: =Y32*AA31/AA32 -> -1172.1526 | AA31: -1100.3
A32: 1993T2 | B32: =B33*L32/L33 -> -340.45596 | L32: -1870.4585 | X32: 37257 | Y32: =Y33*AA32/AA33 -> -617.9821 | AA32: -580.1
A33: 1993T3 | B33: =B34*L33/L34 -> -417.78471 | L33: -2295.3012 | X33: 37622 | Y33: =AB33 -> -829.55122 | AA33: -778.7 | AB33: -829.55122
A34: 1993T4 | B34: =B35*L34/L35 -> -495.11347 | L34: -2720.1439 | X34: 37987 | Y34: =AB34 -> 2597.4318 | AA34: 2074.5 | AB34: 2597.4318
A35: 1994T1 | B35: =B36*L35/L36 -> -448.18395 | L35: -2462.314 | X35: 38353 | Y35: =AB35 -> 1891.0492 | AA35: 1449 | AB35: 1891.0492
A36: 1994T2 | B36: =B37*L36/L37 -> -401.25443 | L36: -2204.4842 | X36: 38718 | Y36: =AB36 -> 7115.5641 | AA36: 7154.3 | AB36: 7115.5641
A37: 1994T3 | B37: =B38*L37/L38 -> -354.32491 | L37: -1946.6543 | X37: 39083 | Y37: =AB37 -> 7078.7728 | AA37: 7458.1 | AB37: 7078.7728
A38: 1994T4 | B38: =B39*L38/L39 -> -307.39539 | L38: -1688.8244 | X38: 39448 | Y38: =AB38 -> -5800.0804 | AA38: -3307.3 | AB38: -5800.0804
A39: 1995T1 | B39: =B40*L39/L40 -> -295.75148 | L39: -1624.853 | X39: 39814 | Y39: =AB39 -> 3518.0596 | AA39: 2570.1 | AB39: 3518.0596
A40: 1995T2 | B40: =B41*L40/L41 -> -284.10757 | L40: -1560.8815 | X40: 40179 | Y40: =AB40 -> 3268.5669 | AA40: 3801.7 | AB40: 3268.5669
A41: 1995T3 | B41: =B42*L41/L42 -> -272.46366 | L41: -1496.9101 | X41: 40544 | Y41: =AB41 -> -3220.1832 | AB41: -3220.1832
A42: 1995T4 | B42: =B43*L42/L43 -> -260.81974 | L42: -1432.9387 | X42: 40909
A43: 1996T1 | B43: =B44*K43/K44 -> -345.05147 | K43: -150.5 | L43: -1895.7062
A44: 1996T2 | B44: =B45*K44/K45 -> -582.57527 | K44: -254.1 | L44: -2358.4737
A45: 1996T3 | B45: =B46*K45/K46 -> -2751.9288 | K45: -1200.3 | L45: -2821.2412
A46: 1996T4 | B46: =B47*K46/K47 -> -3388.1532 | K46: -1477.8 | L46: -3284.0087
A47: 1997T1 | B47: =B48*K47/K48 -> 1022.3153 | K47: 445.9 | L47: -3437.8117
...

Sheet fedfunds
A1: FEDFUNDS
A2: lin | B2: Percent
A3: M | B3: Monthly
A4: 19906 | B4: 1954-07-01 to 2013-01-01
A5: Effective Federal Funds Rate
A6: Board of Governors of the Federal Reserve System
A7: date | B7: value
A8: 19906 | B8: 0.8
A9: 19937 | B9: 1.22
A10: 19968 | B10: 1.06
A11: 19998 | B11: 0.85
A12: 20029 | B12: 0.83
A13: 20059 | B13: 1.28
A14: 20090 | B14: 1.39
A15: 20121 | B15: 1.29
A16: 20149 | B16: 1.35
A17: 20180 | B17: 1.43
A18: 20210 | B18: 1.43
A19: 20241 | B19: 1.64
... A710: 41275 | B710: 0.14

Sheet FEDFUNDS2
A1: FEDFUNDS
A2: lin | B2: Percent
A3: M | B3: Monthly
A4: 19906 | B4: 1954-07-01 to 2013-01-01
A5: Effective Federal Funds Rate
A6: Board of Governors of the Federal Reserve System
A7: date | B7: value | E7: Fed Fund
A8: 19906 | B8: =fedfunds!B8 -> 0.8 | D8: 1986T1 | E8: =AVERAGE(OFFSET($B$386,(C386-1)*3,0,3,1)) -> 7.8266667
A9: 19937 | B9: =fedfunds!B9 -> 1.22 | D9: 1986T2 | E9: =AVERAGE(OFFSET($B$386,(C387-1)*3,0,3,1)) -> 6.92
A10: 19968 | B10: =fedfunds!B10 -> 1.06 | D10: 1986T3 | E10: =AVERAGE(OFFSET($B$386,(C388-1)*3,0,3,1)) -> 6.2066667
A11: 19998 | B11: =fedfunds!B11 -> 0.85 | D11: 1986T4 | E11: =AVERAGE(OFFSET($B$386,(C389-1)*3,0,3,1)) -> 6.2666667
A12: 20029 | B12: =fedfunds!B12 -> 0.83 | D12: 1987T1 | E12: =AVERAGE(OFFSET($B$386,(C390-1)*3,0,3,1)) -> 6.22
A13: 20059 | B13: =fedfunds!B13 -> 1.28 | D13: 1987T2 | E13: =AVERAGE(OFFSET($B$386,(C391-1)*3,0,3,1)) -> 6.65
A14: 20090 | B14: =fedfunds!B14 -> 1.39 | D14: 1987T3 | E14: =AVERAGE(OFFSET($B$386,(C392-1)*3,0,3,1)) -> 6.8433333
A15: 20121 | B15: =fedfunds!B15 -> 1.29 | D15: 1987T4 | E15: =AVERAGE(OFFSET($B$386,(C393-1)*3,0,3,1)) -> 6.9166667
A16: 20149 | B16: =fedfunds!B16 -> 1.35 | D16: 1988T1 | E16: =AVERAGE(OFFSET($B$386,(C394-1)*3,0,3,1)) -> 6.6633333
A17: 20180 | B17: =fedfunds!B17 -> 1.43 | D17: 1988T2 | E17: =AVERAGE(OFFSET($B$386,(C395-1)*3,0,3,1)) -> 7.1566667
A18: 20210 | B18: =fedfunds!B18 -> 1.43 | D18: 1988T3 | E18: =AVERAGE(OFFSET($B$386,(C396-1)*3,0,3,1)) -> 7.9833333
A19: 20241 | B19: =fedfunds!B19 -> 1.64 | D19: 1988T4 | E19: =AVERAGE(OFFSET($B$386,(C397-1)*3,0,3,1)) -> 8.47
... A115: 23163 | B115: =fedfunds!B115 -> 2.99 | D115: 2012T4 | E115: =AVERAGE(OFFSET($B$386,(C493-1)*3,0,3,1)) -> 0.16
A116: 23193 | B116: =fedfunds!B116 -> 3.02
A117: 23224 | B117: =fedfunds!B117 -> 3.49
A118: 23255 | B118: =fedfunds!B118 -> 3.48
A119: 23285 | B119: =fedfunds!B119 -> 3.5
A120: 23316 | B120: =fedfunds!B120 -> 3.48
A121: 23346 | B121: =fedfunds!B121 -> 3.38
A122: 23377 | B122: =fedfunds!B122 -> 3.48
A123: 23408 | B123: =fedfunds!B123 -> 3.48
A124: 23437 | B124: =fedfunds!B124 -> 3.43
A125: 23468 | B125: =fedfunds!B125 -> 3.47
A126: 23498 | B126: =fedfunds!B126 -> 3.5
A127: 23529 | B127: =fedfunds!B127 -> 3.5
... A385: 31382 | B385: =fedfunds!B385 -> 8.27
A386: 31413 | B386: =fedfunds!B386 -> 8.14 | C386: 1
A387: 31444 | B387: =fedfunds!B387 -> 7.86 | C387: 2
A388: 31472 | B388: =fedfunds!B388 -> 7.48 | C388: 3
A389: 31503 | B389: =fedfunds!B389 -> 6.99 | C389: 4
A390: 31533 | B390: =fedfunds!B390 -> 6.85 | C390: 5
A391: 31564 | B391: =fedfunds!B391 -> 6.92 | C391: 6
A392: 31594 | B392: =fedfunds!B392 -> 6.56 | C392: 7
...

Sheet SalarioResto
B1: Minería | C1: Industria Manufacturera | D1: Electricidad Gas y Agua | E1: Construcción | F1: Comercio | G1: Hoteles y Restaurantes | H1: Transporte y Comunicaciones | I1: Intermediación Financiera | J1: Actividades Inmobiliaria y Empresarial | K1: Administración Pública | L1: Enseñanza | M1: Servicios Sociales y Salud | N1: Otros Servicios Comunitarios y Sociales
A2: ponderadores 2009 | B2: 3.57375 | C2: 16.50973 | D2: 1.382 | E2: 10.88111 | F2: 16.90506 | G2: 2.3165 | H2: 7.1729 | I2: 7.06254 | J2: 16.59242 | K2: 5.6614 | L2: 6.65604 | M2: 3.64955 | N2: 1.637
J3: Alquiler | N3: Personales
A4: 40148 | B4: 1810760 | C4: 687226 | D4: 1260225 | E4: 513577 | F4: 646066 | G4: 345693 | H4: 664623 | I4: 1148823 | J4: 590830 | K4: 942565 | L4: 734621 | M4: 634524 | N4: 590218
B6: MIN | C6: IND | D6: EGA | E6: CONS | F6: COM | H6: TRAN | I6: SFIN | K6: SCOM | P6: CMO RESTO
B7: =+B4 -> 1810760 | C7: =+C4 -> 687226 | D7: =+D4 -> 1260225 | E7: =+E4 -> 513577 | F7: =+SUMPRODUCT(F2:G2,F4:G4)/SUM(F2:G2) -> 609866.33 | H7: =+H4 -> 664623 | I7: =+SUMPRODUCT(I2:J2,I4:J4)/SUM(I2:J2) -> 757427.11 | K7: =+SUMPRODUCT(K2:N2,K4:N4)/SUM(K2:N2) -> 767315.72 | P7: =+(C7*C2+E7*E2+F7*SUM(F2:G2)+H7*H2+I7*SUM(I2:J2)+K7*SUM(K2:N2))/SUM(C2,E2:N2) -> 682300.99
B9: CMO RESTO Nom | C9: CMO Resto en $ | F9: CMO Resto Nom. | G9: CMO Resto Nom. en $ | H9: CMO Resto Nom. SA | I9: CMO Resto Nom. en $ SA
A10: 31413 | B10: =+$M15 -> 0 | C10: =+C11*B10/B11 -> #DIV/0! | D10: 1 | E10: 1986T1 | F10: =AVERAGE(OFFSET($B$10,(D10-1)*3,0,3,1)) -> 0 | G10: =AVERAGE(OFFSET($C$10,(D10-1)*3,0,3,1)) -> #DIV/0! | H10: 7.7125911 | I10: 51654.53
A11: 31444 | B11: =+$M16 -> 0 | C11: =+C12*B11/B12 -> #DIV/0! | D11: 2 | E11: 1986T2 | F11: =AVERAGE(OFFSET($B$10,(D11-1)*3,0,3,1)) -> 0 | G11: =AVERAGE(OFFSET($C$10,(D11-1)*3,0,3,1)) -> #DIV/0! | H11: 8.085441 | I11: 54151.666
A12: 31472 | B12: =+$M17 -> 0 | C12: =+C13*B12/B13 -> #DIV/0! | D12: 3 | E12: 1986T3 | F12: =AVERAGE(OFFSET($B$10,(D12-1)*3,0,3,1)) -> 0 | G12: =AVERAGE(OFFSET($C$10,(D12-1)*3,0,3,1)) -> #DIV/0! | H12: 8.3900272 | I12: 56191.61
A13: 31503 | B13: =+$M18 -> 0 | C13: =+C14*B13/B14 -> #DIV/0! | D13: 4 | E13: 1986T4 | F13: =AVERAGE(OFFSET($B$10,(D13-1)*3,0,3,1)) -> 0 | G13: =AVERAGE(OFFSET($C$10,(D13-1)*3,0,3,1)) -> #DIV/0! | H13: 8.8195389 | I13: 59068.234
A14: 31533 | B14: =+$M19 -> 0 | C14: =+C15*B14/B15 -> #DIV/0! | D14: 5 | E14: 1987T1 | F14: =AVERAGE(OFFSET($B$10,(D14-1)*3,0,3,1)) -> 0 | G14: =AVERAGE(OFFSET($C$10,(D14-1)*3,0,3,1)) -> #DIV/0! | H14: 9.1349101 | I14: 61180.41
A15: 31564 | B15: =+$M20 -> 0 | C15: =+C16*B15/B16 -> #DIV/0! | D15: 6 | E15: 1987T2 | F15: =AVERAGE(OFFSET($B$10,(D15-1)*3,0,3,1)) -> 0 | G15: =AVERAGE(OFFSET($C$10,(D15-1)*3,0,3,1)) -> #DIV/0! | H15: 9.49579 | I15: 63597.378
A16: 31594 | B16: =+$M21 -> 0 | C16: =+C17*B16/B17 -> #DIV/0! | D16: 7 | E16: 1987T3 | F16: =AVERAGE(OFFSET($B$10,(D16-1)*3,0,3,1)) -> 0 | G16: =AVERAGE(OFFSET($C$10,(D16-1)*3,0,3,1)) -> #DIV/0! | H16: 10.039106 | I16: 67236.197
A17: 31625 | B17: =+$M22 -> 0 | C17: =+C18*B17/B18 -> #DIV/0! | D17: 8 | E17: 1987T4 | F17: =AVERAGE(OFFSET($B$10,(D17-1)*3,0,3,1)) -> 0 | G17: =AVERAGE(OFFSET($C$10,(D17-1)*3,0,3,1)) -> #DIV/0! | H17: 10.626293 | I17: 71168.839
A18: 31656 | B18: =+$M23 -> 0 | C18: =+C19*B18/B19 -> #DIV/0! | D18: 9 | E18: 1988T1 | F18: =AVERAGE(OFFSET($B$10,(D18-1)*3,0,3,1)) -> 0 | G18: =AVERAGE(OFFSET($C$10,(D18-1)*3,0,3,1)) -> #DIV/0! | H18: 11.183113 | I18: 74898.101
A19: 31686 | B19: =+$M24 -> 0 | C19: =+C20*B19/B20 -> #DIV/0! | D19: 10 | E19: 1988T2 | F19: =AVERAGE(OFFSET($B$10,(D19-1)*3,0,3,1)) -> 0 | G19: =AVERAGE(OFFSET($C$10,(D19-1)*3,0,3,1)) -> #DIV/0! | H19: 11.802899 | I19: 79049.075
A20: 31717 | B20: =+$M25 -> 0 | C20: =+C21*B20/B21 -> #DIV/0! | D20: 11 | E20: 1988T3 | F20: =AVERAGE(OFFSET($B$10,(D20-1)*3,0,3,1)) -> 0 | G20: =AVERAGE(OFFSET($C$10,(D20-1)*3,0,3,1)) -> #DIV/0! | H20: 12.555957 | I20: 84092.626
A21: 31747 | B21: =+$M26 -> 0 | C21: =+C22*B21/B22 -> #DIV/0! | D21: 12 | E21: 1988T4 | F21: =AVERAGE(OFFSET($B$10,(D21-1)*3,0,3,1)) -> 0 | G21: =AVERAGE(OFFSET($C$10,(D21-1)*3,0,3,1)) -> #DIV/0! | H21: 12.85543 | I21: 86098.325
... A117: 34669 | B117: =+$M122 -> 0 | C117: =+C118*B117/B118 -> #DIV/0! | D117: 108 | E117: 2012T4 | F117: =AVERAGE(OFFSET($B$10,(D117-1)*3,0,3,1)) -> 0 | G117: =AVERAGE(OFFSET($C$10,(D117-1)*3,0,3,1)) -> #DIV/0! | H117: 122.43832 | I117: 820021.93
A118: 34700 | B118: =+$M123 -> 0 | C118: =+C119*B118/B119 -> #DIV/0! | D118: 109
A119: 34731 | B119: =+$M124 -> 0 | C119: =+C120*B119/B120 -> #DIV/0! | D119: 110
A120: 34759 | B120: =+$M125 -> 0 | C120: =+C121*B120/B121 -> #DIV/0! | D120: 111
A121: 34790 | B121: =+$M126 -> 0 | C121: =+C122*B121/B122 -> #DIV/0! | D121: 112
A122: 34820 | B122: =+$M127 -> 0 | C122: =+C123*B122/B123 -> #DIV/0! | D122: 113
A123: 34851 | B123: =+$M128 -> 0 | C123: =+C124*B123/B124 -> #DIV/0! | D123: 114
A124: 34881 | B124: =+$M129 -> 0 | C124: =+C125*B124/B125 -> #DIV/0! | D124: 115
A125: 34912 | B125: =+$M130 -> 0 | C125: =+C126*B125/B126 -> #DIV/0! | D125: 116
A126: 34943 | B126: =+$M131 -> 0 | C126: =+C127*B126/B127 -> #DIV/0! | D126: 117
A127: 34973 | B127: =+$M132 -> 0 | C127: =+C128*B127/B128 -> #DIV/0! | D127: 118
A128: 35004 | B128: =+$M133 -> 0 | C128: =+C129*B128/B129 -> #DIV/0! | D128: 119
A129: 35034 | B129: =+$M134 -> 0 | C129: =+C130*B129/B130 -> #DIV/0! | D129: 120
... A296: 40118 | B296: =+$M301 -> 0 | C296: =+C297*B296/B297 -> #DIV/0! | D296: 287
A297: 40148 | B297: =+$M302 -> 0 | C297: =P7 -> 682300.99 | D297: 288
A298: 40179 | B298: =+$M303 -> 0 | C298: =+C297*B298/B297 -> #DIV/0! | D298: 289
A299: 40210 | B299: =+$M304 -> 0 | C299: =+C298*B299/B298 -> #DIV/0! | D299: 290
A300: 40238 | B300: =+$M305 -> 0 | C300: =+C299*B300/B299 -> #DIV/0! | D300: 291
A301: 40269 | B301: =+$M306 -> 0 | C301: =+C300*B301/B300 -> #DIV/0! | D301: 292
A302: 40299 | B302: =+$M307 -> 0 | C302: =+C301*B302/B301 -> #DIV/0! | D302: 293
A303: 40330 | B303: =+$M308 -> 0 | C303: =+C302*B303/B302 -> #DIV/0! | D303: 294
...

Sheet Notas_RTranamil
A1: Autor: | B1: Rodrigo Tranamil
A2: Última
A3: Modificación: | B3: 42247
A5: La base de datos principal es la que se encuentra en la hoja "DatosVinculos", la cual contiene series construidas desde 1986q1 hasta 2014q4. (Ver "Notas_CPerez" para información sobre la base de datos anterior 1986q1 hasta 2014q4).
A6: En su mayoría corresponden a datos efectivos, de lo contrario se destaca el contenido de la celda con letra roja, la explicación de los datos construidos se encuentra en las Notas. (Además ver "Notas_Cperez")
A7: La hoja "DatosSinVinculos" corresponde a la base consolidada sin vinculos.
A9: Notas adicionales a "Notas_CPerez":
A10: 1) La serie IPC fue construdia a partir de los datos extraídos de la Base Siete. Se tomó la serie mensual IPC base 2013=100 y se empalmó hacia atrás utilizando la variación mensual del IPC base 2008=100. Luego, se usó el promedio como método de agregación para que la serie tenga frecuencia trimestral.
A11: 2) Las series PIB Resto, PIB RRNN, PIB Minería son extraídas de la base de datos de la GAM.
A12: 3) La serie PIB Minería del Cobre es extraída de la base de datos de la GAM pero tiene datos efectivos desde 1996q1. Hacia atrás se realiza un empalme de variación anual respecto a la serie PIB Minería.
A13: 4) La serie Consumo Total, Consumo de Gobierno, Consumo Privado son extraídos de la base de datos de la GAM pero tiene datos efectivos desde 1996q1. Hacia atrás se realiza un empalme de variación anual respecto a una serie de Consumo y sus desagregados entregada por el DAC.
A14: 5) La serie IREM y sus desagregados son estraídos de la base de datos de la GAM.
A15: 6) La serie CMO y sus desagregados son estraídos de la base de datos de la GAM.
A16: 7) La serie Empleo y sus desagregados son estraídos de la base de datos de la GAM.
A17: 8) La serie TPM nominal se extrae desde la base siete con datos efectivos a partir de 1995q2.
A18: 9) En esta versión, se agregan las variables horas y desempleo como observables.

Sheet DatosVinculos
A1: Nombre Largo | B1: PIB Real | C1: PIB Real SA | D1: PIB Nominal | E1: PIB Resto Real | F1: PIB Resto Real SA | G1: PIB RRNN Real | H1: PIB RRNN Real SA | I1: PIB Minería Real | J1: PIB Minería Real SA | K1: PIB Minería del Cobre Real | L1: PIB Minería del Cobre Real SA | M1: Consumo Total | N1: Consumo Total SA | O1: Consumo de Gobierno | P1: Consumo de Gobierno SA | Q1: Consumo Privado | R1: Consumo Privado SA | S1: Consumo Durable | T1: Consumo Durable SA | U1: Consumo Habitual | V1: Consumo Habitual SA | W1: FBCF Real | X1: FBCF Real SA | Y1: Balanza Comercial Nominal | Z1: Balanza Comercial Real | AA1: Cuenta Corriente | AB1: IPC | AC1: IPC SA | AD1: IPCSAE | AE1: IPCSAE SA | AF1: IPCSAE Bienes | AG1: IPCSAE Bienes SA | AH1: IPCSAE Servicios | AI1: IPCSAE Servicios SA | AJ1: Meta IPC | AK1: Meta IPC 2 | AL1: TPM Nominal | AM1: TCR | AN1: TCN | AO1: Precio Cobre Nominal | AP1: Precio Petróleo WTI | AQ1: IPE | AR1: PIB Externo Real | AS1: Libor | AT1: FED Funds | AU1: EMBI Chile | AV1: EMBI Chile 2 | AW1: TDI | AX1: CMO Total Real | AY1: CMO Total Real SA | AZ1: CMO Total Real en Pesos | BA1: CMO Total Real en Pesos SA | BB1: CMO Total Nom. | BC1: CMO Total Nom. SA | BD1: CMO Total Nom. en Pesos | BE1: CMO Total Nom. en Pesos SA | BF1: CMO Real Resto | BG1: CMO Real Resto SA | BH1: CMO Real Resto en Pesos | BI1: CMO Real Resto en Pesos SA | BJ1: CMO Nom. Resto | BK1: CMO Nom. Resto SA | BL1: CMO Nom. Resto en Pesos | BM1: CMO Nom. Resto en Pesos SA | BN1: IREM Total Real | BO1: IREM Total Real SA | BP1: IREM Total Real en Pesos | BQ1: IREM Total Real en Pesos SA | BR1: IREM Total Nom. | BS1: IREM Total Nom. SA | BT1: IREM Total Nom. en Pesos | BU1: IREM Total Nom. en Pesos SA | BV1: IREM MINERÍA Real | BW1: IREM MINERÍA Real SA | BX1: IREM MINERÍA Real en Pesos | BY1: IREM MINERÍA Real en Pesos SA | BZ1: IREM MINERÍA Nom. | CA1: IREM MINERÍA Nom. SA | CB1: IREM MINERÍA Nom. en Pesos | CC1: IREM MINERÍA Nom. en Pesos SA | CD1: IREM RESTO Real | CE1: IREM RESTO Real SA | CF1: IREM RESTO Real en Pesos | CG1: IREM RESTO Real en Pesos SA | CH1: IREM RESTO Nom. | CI1: IREM RESTO Nom. SA | CJ1: IREM RESTO Nom. en Pesos | CK1: IREM RESTO Nom. en Pesos SA | CL1: Empleo Total | CM1: Empleo Total SA | CN1: Empleo Minería | CO1: Empleo Minería SA | CP1: Horas Total | CQ1: Horas Total SA | CR1: Horas Minería | CS1: Horas Minería SA | CT1: Empleo Total Resto | CU1: Empleo Total Resto SA | CV1: Horas Resto | CW1: Horas Resto SA | CX1: Población > 15 años | CY1: Fuerza de Trabajo Total | CZ1: Fuerza de Trabajo Total SA | DA1: Tasa Desempleo | DB1: Tasa Desempleo SA | DC1: Tasa vacantes | DD1: Tasa Vacantes SA
A2: Unidad | B2: Mill. $ | C2: Mill. $ | D2: Mill. $ | E2: Mill. $ | F2: Mill. $ | G2: Mill. $ | H2: Mill. $ | I2: Mill. $ | J2: Mill. $ | K2: Mill. $ | L2: Mill. $ | M2: Mill. $ | N2: Mill. $ | O2: Mill. $ | P2: Mill. $ | Q2: Mill. $ | R2: Mill. $ | S2: Mill. $ | T2: Mill. $ | U2: Mill. $ | V2: Mill. $ | W2: Mill. $ | X2: Mill. $ | Y2: Mill. $ | Z2: Mill. $ | AA2: Mill. US $ | AB2: Índice | AC2: Índice | AD2: Índice | AE2: Índice | AF2: Índice | AG2: Índice | AH2: Índice | AI2: Índice | AJ2: Índice | AK2: Índice | AL2: Índice | AM2: Índice | AN2: Índice | AO2: USD/libra | AP2: USD/Barril | AQ2: Índice | AR2: Índice | AS2: Tasa, 3 meses | AT2: Tasa | AU2: Índice | AV2: Índice | AW2: Índice | AX2: Índice | AY2: Índice | AZ2: Pesos | BA2: Pesos | BB2: Índice | BC2: Índice | BD2: Pesos | BE2: Pesos | BF2: Índice | BG2: Índice | BH2: Pesos | BI2: Pesos | BJ2: Índice | BK2: Índice | BL2: Pesos | BM2: Pesos | BN2: Índice | BO2: Índice | BP2: Pesos | BQ2: Pesos | BR2: Índice | BS2: Índice | BT2: Pesos | BU2: Pesos | BV2: Índice | BW2: Índice | BX2: Pesos | BY2: Pesos | BZ2: Índice | CA2: Índice | CB2: Pesos | CC2: Pesos | CD2: Índice | CE2: Índice | CF2: Pesos | CG2: Pesos | CH2: Índice | CI2: Índice | CJ2: Pesos | CK2: Pesos | CL2: miles de personas | CM2: miles de personas | CN2: miles de personas | CO2: miles de personas | CP2: Horas semanales | CQ2: Horas semanales | CR2: Horas semanales | CS2: Horas semanales | CT2: miles de personas | CU2: miles de personas | CV2: Horas semanales | CW2: Horas semanales | CX2: miles de personas | CY2: miles de personas | CZ2: Unidades | DA2: Tasa | DB2: Tasa | DC2: Tasa | DD2: Tasa
